Workbook
Name SECTOR: '[1]업체 SECTOR BACK DATA'!$A$3:$C$373

Sheet 국내
A1: RCK Order no. | B1: Customer PO | C1: NOAH O.C No. | D1: PO receipt date | E1: Period | F1: AX Project number | G1: Business registration number | H1: Customer name | I1: Opportunity | J1: Sector | K1: Industry code | L1: AX Item number | M1: Item name | N1: Currency | O1: Item qty | P1: Sales Unit Price | Q1: Sales amount | R1: ICO Unit | S1: Total ICO | T1: Incoterms | U1: 영업 담당 | V1: 공장발주 Person | W1: AX 입력 CS | X1: 공장 발주 날짜 | Y1: 공장 EXW date | Z1: Requested delivery date | AA1: 납품 주소 | AB1: Remark | AC1: 세금계산서 발행일 | AD1: Power supply | AE1: Motor(kW) | AF1: BASE | AG1: ACT Flange | AH1: Operating time | AI1: Handwheel | AJ1: RPM | AK1: Turns | AL1: Bushing | AM1: MOV | AN1: Gearbox model | AO1: Gearbox Flange | AP1: Gearbox ratio | AQ1: Gearbox position | AR1: Operating mode | AS1: Fail action | AT1: Enclosure | AU1: Cable entry | AV1: Paint | AW1: Cover tube(mm) | AX1: WD code | AY1: Test report | AZ1: Version | BA1: Remark2 | BB1: Model | BC1: Bush | BD1: ALS | BE1: EXT | BF1: DC24V | BG1: Modbus, Profibus | BH1: LCU | BI1: PIU | BJ1: CPT+PIU | BK1: PCU+PIU | BL1: -40 | BM1: -60 | BN1: SCP | BO1: EXP | BP1: Bush-SQ | BQ1: Bush-STAR | BR1: INTEGRAL | BS1: IMS | BT1: BLDC | BU1: HART, Foundation Fieldbus | BV1: ATS
A2: ND-0001 | B2: JK2026010202 | D2: 46027 | E2: P01 | F2: TBD | G2: 794-29-00426 | H2: 제이케이콘트롤 | J2: CPI | L2: 1279970 | M2: NA038 with BFV | N2: KRW | O2: 22 | P2: 875000 | Q2: =표3[[#This Row],[Item qty]]*표3[[#This Row],[Sales Unit Price]] -> 19250000 | R2: {=_xlfn.XLOOKUP($BB2&$BB2,ICO!$E:$E,ICO!$C:$C,0)+SUMPRODUCT((BC2:BV2="Y")*_xlfn.XLOOKUP($BB2&BC$1:BV$1,ICO!$E:$E,ICO!$C:$C,0))} -> 922492.84 | S2: =표3[[#This Row],[ICO Unit]]*표3[[#This Row],[Item qty]] -> 20294842 | T2: DDP | V2: 이용욱 | X2: 46030 | Z2: 46059 | AA2: TBD | AD2: 220V-1Ph-60Hz | AL2: ◇17 | AM2: Y (BFV200A) 신우밸브 사급 | AR2: 내장 PCU | AT2: IP67 | AU2: PF 3/4" | AV2: M/S | BB2: NA038 | BC2: Y | BD2: Y | BK2: Y | BP2: Y
A3: ND-0002 | B3: IAN-2601-0001 | C3: L260005 | D3: 46027 | E3: P01 | F3: TBD | G3: 814-01-00158 | H3: 이안컨트롤즈 | J3: OG | L3: 1279957 | M3: NA015 | N3: KRW | O3: 1 | P3: 812000 | Q3: =표3[[#This Row],[Item qty]]*표3[[#This Row],[Sales Unit Price]] -> 812000 | R3: {=_xlfn.XLOOKUP($BB3&$BB3,ICO!$E:$E,ICO!$C:$C,0)+SUMPRODUCT((BC3:BV3="Y")*_xlfn.XLOOKUP($BB3&BC$1:BV$1,ICO!$E:$E,ICO!$C:$C,0))} -> 787213.35 | S3: =표3[[#This Row],[ICO Unit]]*표3[[#This Row],[Item qty]] -> 787213.35 | T3: DDP | V3: 이용욱 | X3: 46030 | Y3: 46040 | Z3: 46041 | AA3: 대신화물 : 부산사상 괘법지점 신한기공 010-319-3265 | AD3: 220V-1Ph-60Hz | AL3: No 가공 | AR3: 외장 PCU | AT3: IP67 | AU3: PF 3/4" | AV3: M/S | BB3: NA015 | BC3: N | BD3: Y | BK3: Y
A4: ND-0003 | B4: DS-2511-2567_01A | D4: 46027 | E4: P01 | F4: TBD | G4: 292-87-02855 | H4: 주식회사 다윈이엔씨 | J4: CPI | M4: PCU BOARD | N4: KRW | O4: 2 | P4: 600000 | Q4: =표3[[#This Row],[Item qty]]*표3[[#This Row],[Sales Unit Price]] -> 1200000 | R4: 0 | S4: =표3[[#This Row],[ICO Unit]]*표3[[#This Row],[Item qty]] -> 0 | T4: DDP | V4: 이용욱 | W4: 김소정 | X4: 46030 | Z4: 46034 | AA4: 경남 창원시 의창구 평산로 33, 425호(팔용동, 신화더플렉스시티) | AB4: 선수금 진행 | AC4: 46030
A5: ND-0004 | B5: 202512310004 | D5: 46027 | E5: P01 | F5: TBD | G5: 113-86-05741 | H5: 케이에이아이텍(주) | J5: WAPO | L5: 1279932 | M5: SA09 | N5: KRW | O5: 1 | P5: 180000 | Q5: =표3[[#This Row],[Item qty]]*표3[[#This Row],[Sales Unit Price]] -> 180000 | R5: {=_xlfn.XLOOKUP($BB5&$BB5,ICO!$E:$E,ICO!$C:$C,0)+SUMPRODUCT((BC5:BV5="Y")*_xlfn.XLOOKUP($BB5&BC$1:BV$1,ICO!$E:$E,ICO!$C:$C,0))} -> 212993.74 | S5: =표3[[#This Row],[ICO Unit]]*표3[[#This Row],[Item qty]] -> 212993.74 | T5: DDP | V5: 이용욱 | X5: 46030 | AA5: 서울 구로구 구로동 615-3 STX W-TOWER 911호 | AD5: DC24V | AL5: Y | AR5: ON/OFF | AU5: PF 1/2" | AV5: M/S | AX5: ST-82000-A | BB5: SA009S
A6: ND-0005 | B6: NOAH 25- 2783 | D6: 46027 | E6: P01 | F6: TBD | G6: 311-81-51048 | H6: ㈜ 명신일렉트릭 | L6: 1279965 | M6: NA028 | N6: KRW | O6: 1 | P6: 1440000 | Q6: =표3[[#This Row],[Item qty]]*표3[[#This Row],[Sales Unit Price]] -> 1440000 | R6: {=_xlfn.XLOOKUP($BB6&$BB6,ICO!$E:$E,ICO!$C:$C,0)+SUMPRODUCT((BC6:BV6="Y")*_xlfn.XLOOKUP($BB6&BC$1:BV$1,ICO!$E:$E,ICO!$C:$C,0))} -> 512336.3 | S6: =표3[[#This Row],[ICO Unit]]*표3[[#This Row],[Item qty]] -> 512336.3 | T6: DDP | V6: 이용욱 | W6: 방정택 | X6: 46030 | AA6: 충청남도 당진시 송산면 유두골길 101 | AB6: 선수금 진행 | AD6: 220V-1Ph-60Hz | AL6: No 가공 | AR6: ON/OFF | AT6: IP67 | AU6: PF 3/4" | AV6: M/S | AX6: NS-12000-C | BB6: NA028 | BC6: N | BD6: Y
A7: ND-0006 | B7: VT-C35-251218-01 | D7: 46027 | E7: P01 | F7: TBD | G7: 775-88-01381 | H7: 주식회사 브이티엘 | J7: CPI | M7: MA003/SBWG-07-1SM | N7: KRW | O7: 4 | P7: 7250000 | Q7: =표3[[#This Row],[Item qty]]*표3[[#This Row],[Sales Unit Price]] -> 29000000 | R7: {=_xlfn.XLOOKUP($BB7&$BB7,ICO!$E:$E,ICO!$C:$C,0)+SUMPRODUCT((BC7:BV7="Y")*_xlfn.XLOOKUP($BB7&BC$1:BV$1,ICO!$E:$E,ICO!$C:$C,0))} -> 0 | S7: =표3[[#This Row],[ICO Unit]]*표3[[#This Row],[Item qty]] -> 0 | T7: DDP | V7: 이용욱 | X7: 46031 | AA7: 경남 창원시 진해구 남양동 404 ㈜브이티엘 | AD7: 415V-3Ph-50Hz | AE7: 3.7 | AJ7: 82.5 | AN7: SBWG-07-1SM | AO7: F40 / RF | AP7: 272:1 | AR7: INT_ON/OFF | AT7: IP68 | AU7: M40 - 1ea / MA25 - 2ea | AV7: Color : RAL 9002 1st(40 mic) : EP170PTA-2263 2nd(40 mic) : UT2578(S)-I-SHS2002-Y (0004D) | AX7: MX-3A1-A | BA7: Sunshade 적용 Handle 방향 확인 | BB7: MA03 | BR7: Y
A8: ND-0007 | B8: GE-05 | D8: 46027 | E8: P01 | F8: TBD | G8: 113-15-83752 | H8: 굿이엔지 | J8: OG | M8: MS02 | N8: KRW | O8: 3 | P8: 1350000 | Q8: =표3[[#This Row],[Item qty]]*표3[[#This Row],[Sales Unit Price]] -> 4050000 | R8: {=_xlfn.XLOOKUP($BB8&$BB8,ICO!$E:$E,ICO!$C:$C,0)+SUMPRODUCT((BC8:BV8="Y")*_xlfn.XLOOKUP($BB8&BC$1:BV$1,ICO!$E:$E,ICO!$C:$C,0))} -> 0 | S8: =표3[[#This Row],[ICO Unit]]*표3[[#This Row],[Item qty]] -> 0 | T8: DDP | V8: 이용욱 | X8: 46031 | AD8: 380V_3PH_60Hz | AE8: 1.5 | AF8: Non thrust | AJ8: 36.6 | AR8: ON/OFF | BB8: MS02
A9: ND-0008 | B9: 202601050001 | D9: 46027 | E9: P01 | F9: TBD | G9: 113-86-05741 | H9: 케이에이아이텍(주) | J9: CPI | L9: 1279932 | M9: SA09 | N9: KRW | O9: 10 | P9: 180000 | Q9: =표3[[#This Row],[Item qty]]*표3[[#This Row],[Sales Unit Price]] -> 1800000 | R9: {=_xlfn.XLOOKUP($BB9&$BB9,ICO!$E:$E,ICO!$C:$C,0)+SUMPRODUCT((BC9:BV9="Y")*_xlfn.XLOOKUP($BB9&BC$1:BV$1,ICO!$E:$E,ICO!$C:$C,0))} -> 212993.74 | S9: =표3[[#This Row],[ICO Unit]]*표3[[#This Row],[Item qty]] -> 2129937.4 | T9: DDP | V9: 이용욱 | X9: 46031 | AA9: 서울 구로구 구로동 615-3 STX W-TOWER 911호 | AD9: 220V-1Ph-60Hz | AL9: No 가공 | AR9: ON/OFF | AU9: PF 1/2" | AX9: ST-12000-A | BB9: SA009S
A10: ND-0009 | B10: TP-260105-01 | D10: 46028 | E10: P01 | F10: TBD | G10: 606-81-95134 | H10: (주)티엠아이 | J10: CPI | M10: PCU BOARD | N10: KRW | O10: 1 | P10: 330000 | Q10: =표3[[#This Row],[Item qty]]*표3[[#This Row],[Sales Unit Price]] -> 330000 | R10: {=_xlfn.XLOOKUP($BB10&$BB10,ICO!$E:$E,ICO!$C:$C,0)+SUMPRODUCT((BC10:BV10="Y")*_xlfn.XLOOKUP($BB10&BC$1:BV$1,ICO!$E:$E,ICO!$C:$C,0))} -> 0 | S10: =표3[[#This Row],[ICO Unit]]*표3[[#This Row],[Item qty]] -> 0 | T10: DDP | V10: 이용욱 | X10: 46031 | Z10: 46030 | AA10: 경남 김해시 김해대로 2419 2층 티엠아이 / 노병철 이사 010-2866-4509 | AB10: TP-260105-01
A11: ND-0010 | B11: JK2026010601 | D11: 46028 | E11: P01 | F11: TBD | G11: 794-29-00426 | H11: 제이케이콘트롤 | J11: CPI | L11: 1279970 | M11: NA038_INT ON/OFF_방폭 | N11: KRW | O11: 1 | P11: 1288000 | Q11: =표3[[#This Row],[Item qty]]*표3[[#This Row],[Sales Unit Price]] -> 1288000 | R11: {=_xlfn.XLOOKUP($BB11&$BB11,ICO!$E:$E,ICO!$C:$C,0)+SUMPRODUCT((BC11:BV11="Y")*_xlfn.XLOOKUP($BB11&BC$1:BV$1,ICO!$E:$E,ICO!$C:$C,0))} -> 1353373.7 | S11: =표3[[#This Row],[ICO Unit]]*표3[[#This Row],[Item qty]] -> 1353373.7 | T11: DDP | V11: 이용욱 | X11: 46031 | Z11: 46050 | AA11: 서울시 금천구 시흥대로 97 시흥산업용재유통센터 19동 120호 제이케이콘트롤 / 이재강대표 010-2081-0180 | AD11: 220V-1Ph-60Hz | AR11: INT_ON/OFF | AT11: EX d llB T4 | AU11: NPT 1" - 1ea / NPT 3/4" - 2ea | AV11: M/S | AX11: NS-201-B | BB11: NA038 | BO11: Y | BR11: Y
A12: ND-0011 | B12: NM-25104108 | D12: 46029 | E12: P01 | F12: TBD | G12: 606-38-53837 | H12: 노아마린(NOAH MARINE) | J12: CPI | L12: 1279961 | M12: NA019 | N12: KRW | O12: 3 | P12: 1840000 | Q12: =표3[[#This Row],[Item qty]]*표3[[#This Row],[Sales Unit Price]] -> 5520000 | R12: {=_xlfn.XLOOKUP($BB12&$BB12,ICO!$E:$E,ICO!$C:$C,0)+SUMPRODUCT((BC12:BV12="Y")*_xlfn.XLOOKUP($BB12&BC$1:BV$1,ICO!$E:$E,ICO!$C:$C,0))} -> 0 | S12: =표3[[#This Row],[ICO Unit]]*표3[[#This Row],[Item qty]] -> 0 | T12: DDP | V12: 이용욱 | Z12: 46058
A13: NDE-0012 | B13: INCO-260107-002 | C13: N/A | D13: 46029 | E13: P01 | F13: TBD | G13: 238-87-02400 | H13: 주식회사 아이엔씨코리아(I&C KOREA Inc.) | J13: CPI | M13: 수동 핸들 | N13: KRW | O13: 3 | P13: 50000 | Q13: =표3[[#This Row],[Item qty]]*표3[[#This Row],[Sales Unit Price]] -> 150000 | R13: {=_xlfn.XLOOKUP($BB13&$BB13,ICO!$E:$E,ICO!$C:$C,0)+SUMPRODUCT((BC13:BV13="Y")*_xlfn.XLOOKUP($BB13&BC$1:BV$1,ICO!$E:$E,ICO!$C:$C,0))} -> 0 | S13: =표3[[#This Row],[ICO Unit]]*표3[[#This Row],[Item qty]] -> 0 | T13: DDP | V13: 이용욱 | X13: 46029 | Y13: 46029 | AB13: 긴급 발주 건
A14: ND-0013 | B14: N/A | D14: 46029 | E14: P01 | F14: TBD | G14: 117-81-76942 | H14: 오토밸브엔지니어링 | J14: OG | L14: 1280032 | M14: SA005L | N14: KRW | O14: 3 | P14: 530000 | Q14: =표3[[#This Row],[Item qty]]*표3[[#This Row],[Sales Unit Price]] -> 1590000 | R14: {=_xlfn.XLOOKUP($BB14&$BB14,ICO!$E:$E,ICO!$C:$C,0)+SUMPRODUCT((BC14:BV14="Y")*_xlfn.XLOOKUP($BB14&BC$1:BV$1,ICO!$E:$E,ICO!$C:$C,0))} -> 0 | S14: =표3[[#This Row],[ICO Unit]]*표3[[#This Row],[Item qty]] -> 0 | T14: DDP | V14: 이용욱 | Z14: 46029 | AA14: 대신화물-대전대화동, 경성유체기술 최동규 부장님 010-4190-3365
A15: ND-0014 | B15: IAN-2601-0002 | D15: 46029 | E15: P01 | F15: TBD | G15: 814-01-00158 | H15: 이안컨트롤즈 | J15: OG | M15: 3WAY L타입 | N15: KRW | O15: 2 | P15: 85600 | Q15: =표3[[#This Row],[Item qty]]*표3[[#This Row],[Sales Unit Price]] -> 171200 | R15: {=_xlfn.XLOOKUP($BB15&$BB15,ICO!$E:$E,ICO!$C:$C,0)+SUMPRODUCT((BC15:BV15="Y")*_xlfn.XLOOKUP($BB15&BC$1:BV$1,ICO!$E:$E,ICO!$C:$C,0))} -> 0 | S15: =표3[[#This Row],[ICO Unit]]*표3[[#This Row],[Item qty]] -> 0 | T15: DDP | V15: 이용욱 | Z15: 46030
A16: ND-0015 | B16: N/A | D16: 46030 | E16: P01 | F16: TBD | G16: 121-08-40402 | H16: 오성에어테크 | J16: CPI | L16: 1279931 | M16: SA-05X | N16: KRW | O16: 31 | P16: 0 | Q16: =표3[[#This Row],[Item qty]]*표3[[#This Row],[Sales Unit Price]] -> 0 | R16: {=_xlfn.XLOOKUP($BB16&$BB16,ICO!$E:$E,ICO!$C:$C,0)+SUMPRODUCT((BC16:BV16="Y")*_xlfn.XLOOKUP($BB16&BC$1:BV$1,ICO!$E:$E,ICO!$C:$C,0))} -> 0 | S16: =표3[[#This Row],[ICO Unit]]*표3[[#This Row],[Item qty]] -> 0 | T16: DDP | V16: 이용욱 | AA16: 노아엑츄에이션 본사 방문출고
A17: ND-0016 | B17: PO-4-26-0108-0006 Rev.0 | D17: 46030 | E17: P01 | F17: TBD | G17: 312-81-03840 | H17: (주)삼신 | J17: WAPO | M17: Spare | N17: KRW | O17: 25 | P17: 375000 | Q17: =표3[[#This Row],[Item qty]]*표3[[#This Row],[Sales Unit Price]] -> 9375000 | R17: {=_xlfn.XLOOKUP($BB17&$BB17,ICO!$E:$E,ICO!$C:$C,0)+SUMPRODUCT((BC17:BV17="Y")*_xlfn.XLOOKUP($BB17&BC$1:BV$1,ICO!$E:$E,ICO!$C:$C,0))} -> 0 | S17: =표3[[#This Row],[ICO Unit]]*표3[[#This Row],[Item qty]] -> 0 | T17: DDP | V17: 이용욱 | X17: 46031 | AA17: 충남 천안시 서북구 입장면 성진로 1138-11호 (주)삼신 / 박성해 대리 010 8622 5414
A18: ND-0017 | B18: KR26-SA01 FOC 대정밸브 샘플 | D18: 46030 | E18: P01 | F18: 82-15533.001 | G18: 503-81-25251 | H18: 대정밸브 | J18: CPI | L18: 1279949 | M18: Noah NA006 WT | N18: KRW | O18: 1 | P18: 0 | Q18: 0 | R18: 184211 | S18: =표3[[#This Row],[ICO Unit]]*표3[[#This Row],[Item qty]] -> 184211 | T18: DDP | V18: 이용욱 | W18: 이상권 | X18: 46031 | Y18: 46031 | Z18: 46045 | AA18: 대신화물 대구 달서 호산 대정밸브 이 성 국 차장님 053-584-2278 | AB18: 긴급 발주 건 (김한솔) | AD18: 220V-1Ph-60Hz | AL18: ㅁ17 | AR18: ON/OFF | AT18: IP67 | AX18: NS-12000-C | BC18: Y | BP18: Y
A19: ND-0018 | B19: N/A | D19: 46031 | E19: P01 | F19: TBD | G19: 117-81-76942 | H19: 오토밸브 | J19: OG | M19: SA05X-DA | N19: KRW | O19: 2 | R19: {=_xlfn.XLOOKUP($BB19&$BB19,ICO!$E:$E,ICO!$C:$C,0)+SUMPRODUCT((BC19:BV19="Y")*_xlfn.XLOOKUP($BB19&BC$1:BV$1,ICO!$E:$E,ICO!$C:$C,0))} -> 0 | S19: =표3[[#This Row],[ICO Unit]]*표3[[#This Row],[Item qty]] -> 0 | T19: DDP | AA19: 서울특별시 구로구 경인로53가길 10,1112 호(구로동,구로대명벨리온 지식산업센터) | AD19: AC220V | AR19: ON/OFF
B20: 202601090004 | D20: 46031 | E20: P01 | F20: TBD | H20: 케이에이아이텍(주) | J20: CPI | M20: SA09X-PCU(4-25mA)-220V | N20: KRW | O20: 4 | P20: 620000 | Q20: =표3[[#This Row],[Item qty]]*표3[[#This Row],[Sales Unit Price]] -> 2480000 | R20: {=_xlfn.XLOOKUP($BB20&$BB20,ICO!$E:$E,ICO!$C:$C,0)+SUMPRODUCT((BC20:BV20="Y")*_xlfn.XLOOKUP($BB20&BC$1:BV$1,ICO!$E:$E,ICO!$C:$C,0))} -> 0 | S20: =표3[[#This Row],[ICO Unit]]*표3[[#This Row],[Item qty]] -> 0 | T20: DDP | AT20: Ex d IIB T6

Sheet 해외
A1: RCK Order no. | B1: Customer PO | C1: NOAH O.C No. | D1: PO receipt date | E1: Period | F1: AX Project number | G1: Business registration number | H1: Customer name | I1: Opportunity | J1: Sector | K1: Industry code | L1: AX Item number | M1: Item name | N1: Currency | O1: Item qty | P1: Sales Unit Price | Q1: Sales amount | R1: ICO Unit | S1: Total ICO | T1: Incoterms | U1: 영업 담당 | V1: 공장발주 Person | W1: AX 입력 CS | X1: 공장 발주 날짜 | Y1: 공장 EXW date | Z1: Requested delivery date | AA1: 납품 주소 | AB1: Remark | AC1: 세금계산서 발행일 | AD1: Power supply | AE1: Motor(kW) | AF1: ACT Flange | AG1: Operating time | AH1: Handwheel | AI1: RPM | AJ1: Turns | AK1: Bushing | AL1: MOV | AM1: Gearbox model | AN1: Gearbox Flange | AO1: Gearbox ratio | AP1: Gearbox position | AQ1: Operating mode | AR1: Fail action | AS1: Enclosure | AT1: Cable entry | AU1: Paint | AV1: Cover tube(mm) | AW1: WD code | AX1: Test report | AY1: Version | AZ1: Model | BA1: Bush | BB1: ALS | BC1: EXT | BD1: DC24V | BE1: Modbus, Profibus | BF1: LCU | BG1: PIU | BH1: CPT+PIU | BI1: PCU+PIU | BJ1: -40 | BK1: -60 | BL1: SCP | BM1: EXP | BN1: Bush-SQ | BO1: Bush-STAR | BP1: INTEGRAL | BQ1: IMS | BR1: BLDC | BS1: HART, Foundation Fieldbus | BT1: ATS
A2: NO-0001 | B2: 4000446107 | D2: 46027 | E2: P01 | F2: TBD | G2: C-0054 | H2: MRC Global(New Zealand) Ltd. | J2: =_xlfn.XLOOKUP(표3_3[[#This Row],[Business registration number]],'Customer master_해외'!A:A,'Customer master_해외'!J:J) -> CPI | L2: =_xlfn.XLOOKUP(표3_3[[#This Row],[Model]],'Item-mapping'!J:J,'Item-mapping'!A:A) -> 1279930 | M2: SA005L | N2: USD | O2: 1 | P2: 504 | Q2: =표3_3[[#This Row],[Item qty]]*표3_3[[#This Row],[Sales Unit Price]] -> 504 | R2: {=_xlfn.XLOOKUP($AZ2&$AZ2,ICO!$E:$E,ICO!$C:$C,0)+SUMPRODUCT((BA2:BT2="Y")*_xlfn.XLOOKUP($AZ2&BA$1:BT$1,ICO!$E:$E,ICO!$C:$C,0))} -> 513775.44 | S2: =표3_3[[#This Row],[ICO Unit]]*표3_3[[#This Row],[Item qty]] -> 513775.44 | T2: FOB | V2: 방정택 | X2: 46031 | AD2: 24DC | AZ2: SA005L | BC2: Y | BI2: Y
A3: NO-0002 | B3: 068112-00 | D3: 46028 | E3: P01 | F3: TBD | G3: C-0034 | H3: FLOMATIC CORPORATION | J3: =_xlfn.XLOOKUP(표3_3[[#This Row],[Business registration number]],'Customer master_해외'!A:A,'Customer master_해외'!J:J) -> WAPO | L3: =_xlfn.XLOOKUP(표3_3[[#This Row],[Model]],'Item-mapping'!J:J,'Item-mapping'!A:A) -> 1279957 | M3: FCEL-15ALS | N3: USD | O3: 8 | P3: 430 | Q3: =표3_3[[#This Row],[Item qty]]*표3_3[[#This Row],[Sales Unit Price]] -> 3440 | R3: {=_xlfn.XLOOKUP($AZ3&$AZ3,ICO!$E:$E,ICO!$C:$C,0)+SUMPRODUCT((BA3:BT3="Y")*_xlfn.XLOOKUP($AZ3&BA$1:BT$1,ICO!$E:$E,ICO!$C:$C,0))} -> 456209.57 | S3: =표3_3[[#This Row],[ICO Unit]]*표3_3[[#This Row],[Item qty]] -> 3649676.5 | T3: FOB | V3: 방정택 | X3: 46031 | AD3: 120VAC | AZ3: NA015 | BB3: Y
A4: NO-0002 | B4: 068112-00 | D4: 46028 | E4: P01 | F4: TBD | G4: C-0034 | H4: FLOMATIC CORPORATION | J4: =_xlfn.XLOOKUP(표3_3[[#This Row],[Business registration number]],'Customer master_해외'!A:A,'Customer master_해외'!J:J) -> WAPO | L4: =_xlfn.XLOOKUP(표3_3[[#This Row],[Model]],'Item-mapping'!J:J,'Item-mapping'!A:A) -> 1279965 | M4: FCEL-28ALS | N4: USD | O4: 8 | P4: 483 | Q4: =표3_3[[#This Row],[Item qty]]*표3_3[[#This Row],[Sales Unit Price]] -> 3864 | R4: {=_xlfn.XLOOKUP($AZ4&$AZ4,ICO!$E:$E,ICO!$C:$C,0)+SUMPRODUCT((BA4:BT4="Y")*_xlfn.XLOOKUP($AZ4&BA$1:BT$1,ICO!$E:$E,ICO!$C:$C,0))} -> 512336.3 | S4: =표3_3[[#This Row],[ICO Unit]]*표3_3[[#This Row],[Item qty]] -> 4098690.4 | T4: FOB | V4: 방정택 | X4: 46031 | AD4: 120VAC | AZ4: NA028 | BB4: Y
A5: NO-0002 | B5: 068112-00 | D5: 46028 | E5: P01 | F5: TBD | G5: C-0034 | H5: FLOMATIC CORPORATION | J5: =_xlfn.XLOOKUP(표3_3[[#This Row],[Business registration number]],'Customer master_해외'!A:A,'Customer master_해외'!J:J) -> WAPO | L5: =_xlfn.XLOOKUP(표3_3[[#This Row],[Model]],'Item-mapping'!J:J,'Item-mapping'!A:A) -> 1279977 | M5: FCEL-60ALS | N5: USD | O5: 3 | P5: 648 | Q5: =표3_3[[#This Row],[Item qty]]*표3_3[[#This Row],[Sales Unit Price]] -> 1944 | R5: {=_xlfn.XLOOKUP($AZ5&$AZ5,ICO!$E:$E,ICO!$C:$C,0)+SUMPRODUCT((BA5:BT5="Y")*_xlfn.XLOOKUP($AZ5&BA$1:BT$1,ICO!$E:$E,ICO!$C:$C,0))} -> 690790.51 | S5: =표3_3[[#This Row],[ICO Unit]]*표3_3[[#This Row],[Item qty]] -> 2072371.5 | T5: FOB | V5: 방정택 | X5: 46031 | AD5: 120VAC | AZ5: NA060 | BB5: Y
A6: NO-0002 | B6: 068112-00 | D6: 46028 | E6: P01 | F6: TBD | G6: C-0034 | H6: FLOMATIC CORPORATION | J6: =_xlfn.XLOOKUP(표3_3[[#This Row],[Business registration number]],'Customer master_해외'!A:A,'Customer master_해외'!J:J) -> WAPO | L6: =_xlfn.XLOOKUP(표3_3[[#This Row],[Model]],'Item-mapping'!J:J,'Item-mapping'!A:A) -> 1279953 | M6: FCEL-9ALS | N6: USD | O6: 2 | P6: 347 | Q6: =표3_3[[#This Row],[Item qty]]*표3_3[[#This Row],[Sales Unit Price]] -> 694 | R6: {=_xlfn.XLOOKUP($AZ6&$AZ6,ICO!$E:$E,ICO!$C:$C,0)+SUMPRODUCT((BA6:BT6="Y")*_xlfn.XLOOKUP($AZ6&BA$1:BT$1,ICO!$E:$E,ICO!$C:$C,0))} -> 369860.75 | S6: =표3_3[[#This Row],[ICO Unit]]*표3_3[[#This Row],[Item qty]] -> 739721.51 | T6: FOB | V6: 방정택 | X6: 46031 | AD6: 120VAC | AZ6: NA009 | BB6: Y
A7: NO-0003 | B7: 068118-00 | D7: 46030 | E7: P01 | F7: TBD | G7: C-0034 | H7: FLOMATIC CORPORATION | J7: =_xlfn.XLOOKUP(표3_3[[#This Row],[Business registration number]],'Customer master_해외'!A:A,'Customer master_해외'!J:J) -> WAPO | L7: =_xlfn.XLOOKUP(표3_3[[#This Row],[Model]],'Item-mapping'!J:J,'Item-mapping'!A:A) -> 1279985 | M7: FCEL-100ALS | N7: USD | O7: 2 | P7: 734 | Q7: =표3_3[[#This Row],[Item qty]]*표3_3[[#This Row],[Sales Unit Price]] -> 1468 | R7: {=_xlfn.XLOOKUP($AZ7&$AZ7,ICO!$E:$E,ICO!$C:$C,0)+SUMPRODUCT((BA7:BT7="Y")*_xlfn.XLOOKUP($AZ7&BA$1:BT$1,ICO!$E:$E,ICO!$C:$C,0))} -> 801604.82 | S7: =표3_3[[#This Row],[ICO Unit]]*표3_3[[#This Row],[Item qty]] -> 1603209.6 | T7: FOB | V7: 방정택 | X7: 46031 | AD7: 120VAC | AZ7: NA100 | BB7: Y
A8: NO-0003 | B8: 068118-00 | D8: 46030 | E8: P01 | F8: TBD | G8: C-0034 | H8: FLOMATIC CORPORATION | J8: =_xlfn.XLOOKUP(표3_3[[#This Row],[Business registration number]],'Customer master_해외'!A:A,'Customer master_해외'!J:J) -> WAPO | L8: =_xlfn.XLOOKUP(표3_3[[#This Row],[Model]],'Item-mapping'!J:J,'Item-mapping'!A:A) -> 1279965 | M8: FCEL-28ALS | N8: USD | O8: 5 | P8: 483 | Q8: =표3_3[[#This Row],[Item qty]]*표3_3[[#This Row],[Sales Unit Price]] -> 2415 | R8: {=_xlfn.XLOOKUP($AZ8&$AZ8,ICO!$E:$E,ICO!$C:$C,0)+SUMPRODUCT((BA8:BT8="Y")*_xlfn.XLOOKUP($AZ8&BA$1:BT$1,ICO!$E:$E,ICO!$C:$C,0))} -> 512336.3 | S8: =표3_3[[#This Row],[ICO Unit]]*표3_3[[#This Row],[Item qty]] -> 2561681.5 | T8: FOB | V8: 방정택 | X8: 46031 | AD8: 120VAC | AZ8: NA028 | BB8: Y
A9: NO-0003 | B9: 068118-00 | D9: 46030 | E9: P01 | F9: TBD | G9: C-0034 | H9: FLOMATIC CORPORATION | J9: =_xlfn.XLOOKUP(표3_3[[#This Row],[Business registration number]],'Customer master_해외'!A:A,'Customer master_해외'!J:J) -> WAPO | L9: =_xlfn.XLOOKUP(표3_3[[#This Row],[Model]],'Item-mapping'!J:J,'Item-mapping'!A:A) -> 1279973 | M9: FCEL-50ALS | N9: USD | O9: 16 | P9: 603 | Q9: =표3_3[[#This Row],[Item qty]]*표3_3[[#This Row],[Sales Unit Price]] -> 9648 | R9: {=_xlfn.XLOOKUP($AZ9&$AZ9,ICO!$E:$E,ICO!$C:$C,0)+SUMPRODUCT((BA9:BT9="Y")*_xlfn.XLOOKUP($AZ9&BA$1:BT$1,ICO!$E:$E,ICO!$C:$C,0))} -> 654811.84 | S9: =표3_3[[#This Row],[ICO Unit]]*표3_3[[#This Row],[Item qty]] -> 10476989 | T9: FOB | V9: 방정택 | X9: 46031 | AD9: 120VAC | AZ9: NA050 | BB9: Y
A10: NO-0004 | B10: 2040538 | D10: 46030 | E10: P01 | F10: TBD | G10: C-0001 | H10: ASC ENGINEERED SOLUTIONS | J10: =_xlfn.XLOOKUP(표3_3[[#This Row],[Business registration number]],'Customer master_해외'!A:A,'Customer master_해외'!J:J) -> CPI | L10: =_xlfn.XLOOKUP(표3_3[[#This Row],[Model]],'Item-mapping'!J:J,'Item-mapping'!A:A) -> 1279957 | M10: ACTE E-015B-A1A-A1, 120VAC,WITH AUX LIMIT SWITCHES | N10: USD | O10: 100 | P10: 384 | Q10: =표3_3[[#This Row],[Item qty]]*표3_3[[#This Row],[Sales Unit Price]] -> 38400 | R10: {=_xlfn.XLOOKUP($AZ10&$AZ10,ICO!$E:$E,ICO!$C:$C,0)+SUMPRODUCT((BA10:BT10="Y")*_xlfn.XLOOKUP($AZ10&BA$1:BT$1,ICO!$E:$E,ICO!$C:$C,0))} -> 456209.57 | S10: =표3_3[[#This Row],[ICO Unit]]*표3_3[[#This Row],[Item qty]] -> 45620957 | T10: FOB | V10: 방정택 | X10: 46031 | AD10: 120VAC | AZ10: NA015 | BB10: Y
A11: NO-0004 | B11: 2040538 | D11: 46030 | E11: P01 | F11: TBD | G11: C-0001 | H11: ASC ENGINEERED SOLUTIONS | J11: =_xlfn.XLOOKUP(표3_3[[#This Row],[Business registration number]],'Customer master_해외'!A:A,'Customer master_해외'!J:J) -> CPI | L11: =_xlfn.XLOOKUP(표3_3[[#This Row],[Model]],'Item-mapping'!J:J,'Item-mapping'!A:A) -> 1280044 | M11: ACTE E-SR2600-D1A-A1CW, 24VDC, AUX LIMIT SWITCHES, FAIL-CW | N11: USD | O11: 39 | P11: 2959.72 | Q11: =표3_3[[#This Row],[Item qty]]*표3_3[[#This Row],[Sales Unit Price]] -> 115429.08 | R11: {=_xlfn.XLOOKUP($AZ11&$AZ11,ICO!$E:$E,ICO!$C:$C,0)+SUMPRODUCT((BA11:BT11="Y")*_xlfn.XLOOKUP($AZ11&BA$1:BT$1,ICO!$E:$E,ICO!$C:$C,0))} -> 4560656.5 | S11: =표3_3[[#This Row],[ICO Unit]]*표3_3[[#This Row],[Item qty]] -> 1.778656e+08 | T11: FOB | V11: 방정택 | X11: 46031 | AD11: 120VAC | AR11: Fail Close | AZ11: SR30 | BB11: Y | BD11: Y
A12: NO-0005 | B12: 068087-00 | D12: 46020 | E12: P01 | F12: TBD | G12: C-0034 | H12: FLOMATIC CORPORATION | J12: =_xlfn.XLOOKUP(표3_3[[#This Row],[Business registration number]],'Customer master_해외'!A:A,'Customer master_해외'!J:J) -> WAPO | L12: =_xlfn.XLOOKUP(표3_3[[#This Row],[Model]],'Item-mapping'!J:J,'Item-mapping'!A:A) -> 1279953 | M12: FCEL-9ALS | N12: USD | O12: 4 | P12: 347 | Q12: =표3_3[[#This Row],[Item qty]]*표3_3[[#This Row],[Sales Unit Price]] -> 1388 | R12: {=_xlfn.XLOOKUP($AZ12&$AZ12,ICO!$E:$E,ICO!$C:$C,0)+SUMPRODUCT((BA12:BT12="Y")*_xlfn.XLOOKUP($AZ12&BA$1:BT$1,ICO!$E:$E,ICO!$C:$C,0))} -> 369860.75 | S12: =표3_3[[#This Row],[ICO Unit]]*표3_3[[#This Row],[Item qty]] -> 1479443 | T12: FOB | V12: 방정택 | X12: 46031 | AD12: 120VAC | AZ12: NA009 | BB12: Y

Sheet Item detail
A1: Item number | B1: Item name | C1: Search name | D1: Item group | E1: Main group | F1: Item type | G1: Global item type | H1: Status | I1: Feature group | J1: Key
A2: 1279949 | B2: Noah NA006 WT | C2: NOAH/NA006 | D2: Noah-NA | E2: ELActuator | F2: Item | G2: Rotork Price List Items | I2: Noah-NA | J2: =MID(B2,6,5) -> NA006
A3: 1279950 | B3: Noah NA006 EXP | C3: NOAH/NA006X | D3: Noah-NA | E3: ELActuator | F3: Item | G3: Rotork Price List Items | I3: Noah-NA | J3: =MID(B3,6,5) -> NA006
A4: 1279951 | B4: Noah NA006 -40 | C4: NOAH/NA006CW1 | D4: Noah-NA | E4: ELActuator | F4: Item | G4: Rotork Price List Items | I4: Noah-NA | J4: =MID(B4,6,5) -> NA006
A5: 1279952 | B5: Noah NA006 -60 | C5: NOAH/NA006CW2 | D5: Noah-NA | E5: ELActuator | F5: Item | G5: Rotork Price List Items | I5: Noah-NA | J5: =MID(B5,6,5) -> NA006
A6: 1279953 | B6: Noah NA009 WT | C6: NOAH/NA009 | D6: Noah-NA | E6: ELActuator | F6: Item | G6: Rotork Price List Items | I6: Noah-NA | J6: =MID(B6,6,5) -> NA009
A7: 1279954 | B7: Noah NA009 EXP | C7: NOAH/NA009X | D7: Noah-NA | E7: ELActuator | F7: Item | G7: Rotork Price List Items | I7: Noah-NA | J7: =MID(B7,6,5) -> NA009
A8: 1279955 | B8: Noah NA009 -40 | C8: NOAH/NA009CW1 | D8: Noah-NA | E8: ELActuator | F8: Item | G8: Rotork Price List Items | I8: Noah-NA | J8: =MID(B8,6,5) -> NA009
A9: 1279956 | B9: Noah NA009 -60 | C9: NOAH/NA009CW2 | D9: Noah-NA | E9: ELActuator | F9: Item | G9: Rotork Price List Items | I9: Noah-NA | J9: =MID(B9,6,5) -> NA009
A10: 1279957 | B10: Noah NA015 WT | C10: NOAH/NA015 | D10: Noah-NA | E10: ELActuator | F10: Item | G10: Rotork Price List Items | I10: Noah-NA | J10: =MID(B10,6,5) -> NA015
A11: 1279958 | B11: Noah NA015 EXP | C11: NOAH/NA015X | D11: Noah-NA | E11: ELActuator | F11: Item | G11: Rotork Price List Items | I11: Noah-NA | J11: =MID(B11,6,5) -> NA015
A12: 1279959 | B12: Noah NA015 -40 | C12: NOAH/NA015CW1 | D12: Noah-NA | E12: ELActuator | F12: Item | G12: Rotork Price List Items | I12: Noah-NA | J12: =MID(B12,6,5) -> NA015
A13: 1279960 | B13: Noah NA015 -60 | C13: NOAH/NA015CW2 | D13: Noah-NA | E13: ELActuator | F13: Item | G13: Rotork Price List Items | I13: Noah-NA | J13: =MID(B13,6,5) -> NA015
... A190: Noah-SR | B190: Noah-SR | C190: Noah-SR | D190: Noah-SR | E190: ELActuator | F190: BOM | G190: BOM Template Items | I190: Noah-SR | J190: =MID(B190,6,5) -> SR
B191: MA03 | J191: =MID(B191,6,5)

Sheet Item-mapping
A1: Item number | B1: Item name | C1: Search name | D1: Item group | E1: Main group | F1: Item type | G1: Global item type | H1: Status | I1: Feature group | J1: Key
A2: 1279949 | B2: Noah NA006 WT | C2: NOAH/NA006 | D2: Noah-NA | E2: ELActuator | F2: Item | G2: Rotork Price List Items | I2: Noah-NA | J2: NA006
A3: 1279953 | B3: Noah NA009 WT | C3: NOAH/NA009 | D3: Noah-NA | E3: ELActuator | F3: Item | G3: Rotork Price List Items | I3: Noah-NA | J3: NA009
A4: 1279957 | B4: Noah NA015 WT | C4: NOAH/NA015 | D4: Noah-NA | E4: ELActuator | F4: Item | G4: Rotork Price List Items | I4: Noah-NA | J4: NA015
A5: 1279961 | B5: Noah NA019 WT | C5: NOAH/NA019 | D5: Noah-NA | E5: ELActuator | F5: Item | G5: Rotork Price List Items | I5: Noah-NA | J5: NA019
A6: 1279965 | B6: Noah NA028 WT | C6: NOAH/NA028 | D6: Noah-NA | E6: ELActuator | F6: Item | G6: Rotork Price List Items | I6: Noah-NA | J6: NA028
A7: 1279969 | B7: Noah NA038 WT | C7: NOAH/NA038 | D7: Noah-NA | E7: ELActuator | F7: Item | G7: Rotork Price List Items | I7: Noah-NA | J7: NA038
A8: 1279973 | B8: Noah NA050 WT | C8: NOAH/NA050 | D8: Noah-NA | E8: ELActuator | F8: Item | G8: Rotork Price List Items | I8: Noah-NA | J8: NA050
A9: 1279977 | B9: Noah NA060 WT | C9: NOAH/NA060 | D9: Noah-NA | E9: ELActuator | F9: Item | G9: Rotork Price List Items | I9: Noah-NA | J9: NA060
A10: 1279981 | B10: Noah NA080 WT | C10: NOAH/NA080 | D10: Noah-NA | E10: ELActuator | F10: Item | G10: Rotork Price List Items | I10: Noah-NA | J10: NA080
A11: 1279985 | B11: Noah NA100 WT | C11: NOAH/NA100 | D11: Noah-NA | E11: ELActuator | F11: Item | G11: Rotork Price List Items | I11: Noah-NA | J11: NA100
A12: 1279989 | B12: Noah NA120 WT | C12: NOAH/NA120 | D12: Noah-NA | E12: ELActuator | F12: Item | G12: Rotork Price List Items | I12: Noah-NA | J12: NA120
A13: 1279993 | B13: Noah NA150 WT | C13: NOAH/NA150 | D13: Noah-NA | E13: ELActuator | F13: Item | G13: Rotork Price List Items | I13: Noah-NA | J13: NA150
... A37: 1280048 | B37: Noah SR50 WT | C37: NOAH/SR50 | D37: Noah-SR | E37: ELActuator | F37: Item | G37: Rotork Price List Items | I37: Noah-SR | J37: SR50

Sheet Industry code
A1: Category | B1: New Industry Code | C1: New AX/MTMS Description | D1: Old CE Code
A2: Oil & Gas | B2: 10 | C2: O&G - Upstream - Offshore | D2: A1, A2, A3, A4, A5
A3: Oil & Gas | B3: 11 | C3: O&G - Upstream - Onshore | D3: A6, A7, A8
A4: Oil & Gas | B4: 12 | C4: O&G - Upstream - Upstream carbon capture, utilisation & storage | D4: A9
A5: Oil & Gas | B5: 13 | C5: O&G - Midstream - Pipeline - liquids | D5: C2, C4, C5, C6, C7, C8
A6: Oil & Gas | B6: 14 | C6: O&G - Midstream - Pipeline - gas | D6: D2, D4, D5, D6, D8, D9
A7: Oil & Gas | B7: 15 | C7: O&G - Midstream - Terminals, storage & tank farms - liquid | D7: C3
A8: Oil & Gas | B8: 16 | C8: O&G - Midstream - Terminals, storage & tank farms - gas | D8: D3
A9: Oil & Gas | B9: 17 | C9: O&G - Midstream - LNG - liquefaction | D9: E2, E4
A10: Oil & Gas | B10: 18 | C10: O&G - Midstream - LNG - regasification | D10: E3, E5
A11: Oil & Gas | B11: 19 | C11: O&G - Midstream - LNG terminals & storage | D11: E1
A12: Oil & Gas | B12: 20 | C12: O&G - Midstream - Midstream carbon capture, utilisation & storage | D12: DA
A13: Oil & Gas | B13: 21 | C13: O&G - Downstream - Refining | D13: B1, B2, B3, B4, B5, B6
... A68: Chemical, Process & Industrial | B68: 93 | C68: CPI - Process - Pulp & paper and cement | D68: T3, T6
A69: Chemical, Process & Industrial | B69: 7G | C69: CPI - Process - HVAC Industrial | D69: Depreciated, 79
A70: Chemical, Process & Industrial | B70: G2 | C70: CPI - Industrial - GENERAL INDUSTRIAL USE | D70: Depreciated, 85
A71: Water & Power | B71: 4G | C71: W&P - Power - FOSSIL POWER - COAL | D71: Depreciated, 49

Sheet Customer master_국내
A1: 관리팀 Code | B1: 사업자번호 | C1: 거래처명 | D1: Customer Name ENG | E1: End country | F1: Currency | G1: Type | H1: OEM | I1: OEM 추가 설명 | J1: Reseller | K1: Reseller 추가 설명 | L1: Sector | M1: Sector 추가 설명 | N1: Payment Term | O1: Incoterms | P1: REMARK | Q1: RCK code mapping
A2: 005280 | B2: 261-85-00499 | C2: 주식회사티에스넥스젠 | D2: TS NEXGEN | E2: KOREA | F2: KRW | G2: TP | H2: N | J2: N | L2: CPI
A3: 007414 | B3: 119-81-42375 | C3: 욱삼건설주식회사 | D3: WOOKSAM CONSTRUCTION | E3: KOREA | F3: KRW | G3: TP | H3: N | J3: N | L3: WAPO
A4: 003547 | B4: 312-85-45076 | C4: (주) 센추리 아산공장 | D4: CENTURY | E4: KOREA | F4: KRW | G4: TP | H4: N | J4: N | L4: CPI
A5: 005091 | B5: 794-29-00426 | C5: 제이케이콘트롤 | D5: JK CONSTROLS | E5: KOREA | F5: KRW | G5: TP | H5: N | J5: Y | L5: CPI
A6: 004257 | B6: 306-82-00471 | C6: 한국수자원공사 | D6: K-WATER | E6: KOREA | F6: KRW | G6: TP | H6: N | J6: N | L6: WAPO
A7: 003467 | B7: 117-81-76942 | C7: 오토밸브엔지니어링 | D7: AUTO VALVE | E7: KOREA | F7: KRW | G7: TP | H7: N | J7: Y | L7: CPI
A8: 007705 | B8: 215-81-44948 | C8: 유텍종합건설(주) | D8: YUTEK TOTAL CONSTRUCTION | E8: KOREA | F8: KRW | G8: TP | H8: N | J8: N | L8: WAPO
A9: 006794 | B9: 775-88-01381 | C9: 주식회사 브이티엘 | D9: VTL | E9: KOREA | F9: KRW | G9: TP | H9: N | J9: Y | L9: CPI
A10: 007498 | B10: 247-03-02821 | C10: 글로브이 | D10: GLOV | E10: KOREA | F10: KRW | G10: TP | H10: N | J10: N | L10: WAPO
A11: 002271 | B11: 113-15-83752 | C11: 굿이엔지 | D11: GOODENG | E11: KOREA | F11: KRW | G11: TP | H11: N | I11: 3% 정도는 명판없이 나감 | J11: Y | L11: OG
A12: 006381 | B12: 394-81-01785 | C12: 유나텍 주식회사 | D12: YUNA TECH | E12: KOREA | F12: KRW | G12: TP | H12: N | J12: N | L12: CPI | M12: 단발성 거래 CPI로 분류
A13: 007506 | B13: 674-87-02305 | C13: 테크노아이앤피주식회사 | D13: TECHNO INP | E13: KOREA | F13: KRW | G13: TP | H13: N | J13: N | L13: WAPO
A14: 004174 | B14: 130-86-94744 | C14: 지콘(주) | D14: Z CON | E14: KOREA | F14: KRW | G14: TP | H14: N | J14: Y | L14: OG
A15: 005399 | B15: 606-02-51145 | C15: 경진산업 | D15: KYUNGJIN INDUSTRY | E15: KOREA | F15: KRW | G15: TP | H15: N | J15: N | L15: WAPO
A16: 004563 | B16: 814-01-00158 | C16: 이안컨트롤즈 | D16: IAN CONTROLS | E16: KOREA | F16: KRW | G16: TP | H16: N | J16: Y | L16: OG
A17: 006972 | B17: 105-49-01055 | C17: 아크솔루션 | D17: ARK SOLUTION | E17: KOREA | F17: KRW | G17: TP | H17: N | J17: Y | L17: WAPO
A18: 001845 | B18: 139-81-10936 | C18: (주)현대밸브 | D18: HYUNDAI VALVE | E18: KOREA | F18: KRW | G18: TP | H18: N | J18: N | L18: WAPO
A19: 007438 | B19: 113-86-01707 | C19: 미래밸브콘트롤(주) | D19: MIRAE VALVE CONTROL | E19: KOREA | F19: KRW | G19: TP | H19: N | J19: N | L19: CPI
A20: 007445 | B20: 504-82-08024 | C20: 한국농어촌공사 경북지역본부 | D20: KOREA RURAL COMMUNITY COR (GYEONGBUK) | E20: KOREA | F20: KRW | G20: TP | H20: N | J20: N | L20: WAPO
A21: 002557 | B21: 113-86-05741 | C21: 케이에이아이텍(주) | D21: KAI TECH | E21: KOREA | F21: KRW | G21: TP | H21: N | J21: Y | L21: CPI
A22: 001032 | B22: 139-81-40027 | C22: 상미에어텍(주) | D22: SANGMI AIRTECH | E22: KOREA | F22: KRW | G22: TP | H22: N | J22: Y | L22: CPI
A23: 004322 | B23: 602-81-13237 | C23: (주)호페코리아 | D23: HOPPE KOREA | E23: KOREA | F23: KRW | G23: TP | H23: N | J23: Y | L23: CPI
A24: 002725 | B24: 131-85-33796 | C24: 삼원알텍2공장 | D24: SAMWON ALTECH (PLANT 2) | E24: KOREA | F24: KRW | G24: TP | H24: N | J24: N | L24: CPI | M24: 단발성 거래 CPI로 분류
A25: 007437 | B25: 113-86-17723 | C25: 주식회사 에스제이브이 | D25: SJV | E25: KOREA | F25: KRW | G25: TP | H25: N | J25: N | L25: WAPO
A26: 002430 | B26: 606-81-95134 | C26: (주)티엠아이 | D26: TMI | E26: KOREA | F26: KRW | G26: TP | H26: Partial | I26: 5% 정도는 OEM(자체 명판으로 요청) | J26: Y | L26: OG
A27: 004955 | B27: 605-38-89706 | C27: 동광브이엔티(V&T) | D27: DONGKWANG V&T | E27: KOREA | F27: KRW | G27: TP | H27: N | J27: Y | L27: CPI
A28: 007391 | B28: 669-87-02230 | C28: 자이씨앤에이㈜ | D28: XI C&A | E28: KOREA | F28: KRW | G28: TP | H28: N | J28: N | L28: WAPO
A29: 006047 | B29: 609-81-04684 | C29: 두산에너빌리티(주) | D29: DOOSAN ENERBILITY | E29: KOREA | F29: KRW | G29: TP | H29: N | J29: N | L29: WAPO
A30: 006370 | B30: 134-85-55479 | C30: 영풍정밀(주)밸브공장 | D30: YOUNGPOONG PRECISION | E30: KOREA | F30: KRW | G30: TP | H30: N | J30: N | L30: CPI
A31: 004048 | B31: 603-81-10081 | C31: 하이에어코리아(주) | D31: HI-AIR KOREA | E31: KOREA | F31: KRW | G31: TP | H31: N | J31: N | L31: CPI
A32: 004723 | B32: 622-81-02020 | C32: (주)비와이 | D32: BY | E32: KOREA | F32: KRW | G32: TP | H32: N | J32: Y | L32: CPI
A33: 000736 | B33: 417-81-12417 | C33: (주)에스피씨 | D33: SPC | E33: KOREA | F33: KRW | G33: TP | H33: N | J33: N | L33: WAPO
A34: 007440 | B34: 423-86-00018 | C34: 주식회사 대상엔지니어링 | D34: DAESANG ENG | E34: KOREA | F34: KRW | G34: TP | H34: N | J34: N | L34: WAPO
A35: 005398 | B35: 387-63-00159 | C35: 고성테크 | D35: KOSUNG TECH | E35: KOREA | F35: KRW | G35: TP | H35: N | J35: Y | L35: CPI
A36: 005967 | B36: 632-81-00126 | C36: (주)휴텍 | D36: HUE TECH | E36: KOREA | F36: KRW | G36: TP | H36: N | J36: N | L36: CPI
A37: 001112 | B37: 113-81-65249 | C37: (주)대정밸브(서울) | D37: DAEJUNG VALVE-SEOUL | E37: KOREA | F37: KRW | G37: TP | H37: N | J37: Y | L37: CPI
A38: 003115 | B38: 503-81-86321 | C38: (주)포엠엔지니어링 | D38: 4M ENG | E38: KOREA | F38: KRW | G38: TP | H38: N | J38: Y | L38: OG
... A69: 007553 | B69: 206-86-06585 | C69: 주식회사 상지일렉스 | D69: SANGJI ELECS | E69: KOREA | F69: KRW | G69: TP | H69: N | J69: N | L69: CPI
A70: 006567 | B70: 517-10-01904 | C70: 대신ENG | D70: DAESHIN ENG | E70: KOREA | F70: KRW | G70: TP | H70: N | J70: Y | L70: CPI | M70: 단발성 거래 CPI로 분류
...

Sheet Customer master_해외
A1: C-code by 해외 | B1: 고객명 | C1: 고객코드 | D1: Country | E1: Currency | F1: Type(TP/IC) | G1: OEM(Y/N) | H1: Reseller(Y/N) | I1: INCOTERMS | J1: Sector | K1: 비고 | M1: Payment Terms
A2: C-0095 | B2: WATERGATES GMBH | C2: 002352 | D2: GERMANY | E2: EUR | F2: T P | G2: Y | H2: Y | J2: CPI | K2: WATERGATES | M2: 60일
A3: C-0070 | B3: ROTORK CONTROL INC | C3: 002821 | D3: USA | E3: USD | F3: IC | G3: IC | H3: IC | J3: IC | K3: ROTORK CONTROLS MILWAUKEE | M3: 60일
A4: C-0076 | B4: ROTORK SWEDEN AB | C4: 003012 | D4: SWEDEN | E4: SEK | F4: IC | G4: IC | H4: IC | J4: IC | K4: RSA | M4: 60일
A5: C-0079 | B5: SECTORIEL SA | C5: 001883 | D5: FRANCE | E5: EUR | F5: T P | G5: Y | H5: Y | J5: CPI | K5: SECTORIEL | M5: 60일
A6: C-0075 | B6: ROTORK CONTROLS SINGAPORE | C6: 002576 | D6: SINGAPORE | E6: USD | F6: IC | G6: IC | H6: IC | J6: IC | K6: ROTORK SG | M6: 30일
A7: C-0065 | B7: PROVAL | C7: 002094 | D7: S. AFRICA | E7: USD | F7: T P | G7: N | H7: Y | J7: CPI | K7: PROVAL ACTUATION SA(PTY) LTD | M7: 30일
A8: C-0010 | B8: SHANDONG COPES | C8: 005378 | D8: CHINA | E8: USD | F8: T P | G8: N | H8: Y | J8: CPI | K8: Shandong COPES Automation Equipment Co., Ltd. | M8: 선불
A9: C-0066 | B9: PVD PRESES | C9: 001382 | D9: TURKEY | E9: USD | F9: T P | G9: N | H9: Y | J9: CPI | K9: PVD Proses Vana Donanim San. Ve Tic. Ltd. Sti. | M9: 30일
A10: C-0049 | B10: MESON AB | C10: 004321 | D10: SWEDEN | E10: EUR | F10: T P | G10: Y | H10: Y | J10: CPI | M10: 30일
A11: C-0054 | B11: MRC TRANSMARK PTE LTD | C11: 004678 | D11: New Zealand | E11: USD | F11: T P | G11: Y | H11: Y | J11: CPI | K11: MRC Global(New Zealand) Ltd. | M11: 60일
A12: C-0094 | B12: W&O EUROPE | C12: 004065 | D12: NETHERLAND | E12: EUR | F12: T P | G12: N | H12: Y | J12: CPI | M12: 선불
A13: C-0003 | B13: ACRODYNE | C13: 001095 | D13: AUSTRALIA | E13: USD | F13: T P | G13: Y | H13: Y | J13: WAPO | M13: 30일
A14: C-0035 | B14: FRESEVALVES | C14: 006282 | D14: DENMARK | E14: USD | F14: T P | G14: Y | H14: Y | J14: CPI | K14: FRESE DK | M14: 60일
A15: C-0048 | B15: NANJING KUNHUI FLUID EQUIPMENT | C15: 005842 | D15: CHINA | E15: USD | F15: T P | G15: N | H15: Y | J15: CPI | M15: 선불
A16: C-0062 | B16: OKM | C16: 001097 | D16: MALAYSIA | E16: USD | F16: T P | G16: N | H16: Y | J16: CPI | K16: OKM VALVE(M) SDN BHD | M16: 30일
B17: ASENI LLC | C17: 008068 | D17: UAE | E17: USD | F17: T P | G17: N | H17: Y | J17: CPI
A18: C-0042 | B18: THE JARDINE ENGINEERING | C18: 003109 | D18: HONG KONG | E18: USD | F18: T P | G18: N | H18: Y | J18: CPI | M18: 30일
A19: C-0028 | B19: FAGERBERG NORGE AS | C19: 004318 | D19: NORWAY | E19: EUR | F19: T P | G19: N | H19: Y | J19: WAPO | K19: FAGERBERG AS | M19: 30일
A20: C-0006 | B20: AN THINH PHAT INDUSTRIAL | C20: 006452 | D20: VIETNAM | E20: USD | F20: T P | G20: N | H20: Y | J20: CPI | M20: 선불
A21: C-0004 | B21: ADVANCED COMPONENT TECHNOL | C21: 002613 | D21: U.K. | E21: GBP | F21: T P | G21: N | H21: Y | J21: CPI | M21: 60일
A22: C-0077 | B22: RUNFLOW INDUSTRY | C22: 003446 | D22: CHINA | E22: USD | F22: T P | G22: N | H22: Y | J22: CPI | K22: SHANGHAI RUNFLOW CONTROLS CO., LTD | M22: 선불
A23: C-0091 | B23: CV URIPINDO DIGDAYA AGUNG | C23: 005902 | D23: INDONESIA | E23: USD | F23: T P | G23: N | H23: Y | J23: CPI | K23: URIPINDO | M23: 선불
A24: C-0008 | B24: BROEN SPOLKA Z OGRANICZONA | C24: 003449 | D24: POLAND | E24: EUR | F24: T P | G24: N | H24: Y | J24: WAPO | K24: BROEN | M24: 60일
A25: C-0059 | B25: NORDIC FLOW CONTROL PL | C25: 004455 | D25: SINGAPORE | E25: USD | F25: T P | G25: Y | H25: Y | J25: CPI | M25: 60일
A26: C-0108 | B26: DL TECH PTE LTD | C26: 005980 | D26: SINGAPORE | E26: USD | F26: T P | G26: N | H26: Y | J26: WAPO | M26: 선불
A27: C-0093 | B27: VALVECO LOGISTICS&SERVICES BV | C27: 007480 | D27: NETHERLAND | E27: EUR | F27: T P | G27: N | H27: Y | J27: CPI | M27: 60일
A28: C-0034 | B28: FLOMATIC CORPORATION | C28: 003729 | D28: USA | E28: USD | F28: T P | G28: Y | H28: Y | J28: WAPO | K28: FLOMATIC CORPORATION | M28: 60일
A29: C-0007 | B29: AXFLOW LIMITED | C29: 004151 | D29: IRELAND | E29: EUR | F29: T P | G29: N | H29: Y | J29: CPI | M29: 60일
A30: C-0061 | B30: CHANGSHA OUKE CONTROL VALVE | C30: 002238 | D30: CHINA | E30: USD | F30: T P | G30: N | H30: Y | J30: CPI | M30: 선불
A31: C-0085 | B31: NANTONG OK CRAGON INTERNATIONA | C31: 008224 | D31: CHINA | E31: USD | F31: T P | G31: N | H31: Y | J31: CPI | K31: NANTONG OK DRAGON INTERNALTIONAL TRADE(TCV) | M31: 선불
A32: C-0080 | B32: SEVAL COMPANY LIMITED | C32: 007509 | D32: VIETNAM | E32: USD | F32: T P | G32: N | H32: Y | J32: CPI | M32: 선불
B33: WOG VALVE SHANGHAIL CO.,LTD | C33: 008456 | D33: CHINA | E33: USD | F33: T P | G33: N | H33: Y | J33: CPI
A34: C-0053 | B34: MRC TRANSMARK B V | C34: 003197 | D34: NETHERLAND | E34: EUR | F34: T P | G34: Y | H34: Y | J34: OG | K34: MRC Global(Netherland) BV(MRC NL) | M34: 60일
B35: WELLSRING IMPORT AND EXPORT CO | C35: 008376 | D35: CHINA | E35: USD | F35: T P | G35: N | H35: Y | J35: WAPO
B36: ZIGONG ZIGAO VALVE CO.,LTD | C36: 008355 | D36: CHINA | E36: USD | F36: T P | G36: N | H36: Y | J36: CPI
B37: HANSAHANDELSHAUS OU | C37: 008356 | D37: ESTONIA | E37: USD | F37: T P | G37: N | H37: Y | J37: CPI
A38: C-0069 | B38: RAPHAEL VALVES INDUSTRIES | C38: 004388 | D38: ISRAEL | E38: USD | F38: T P | G38: N | H38: Y | J38: CPI | M38: 30일
A39: C-0071 | B39: ROCONSULT TECH SRL | C39: 007679 | D39: ROMANIA | E39: EUR | F39: T P | G39: N | H39: Y | J39: CPI | M39: 선불
A40: C-0037 | B40: FRONTLINE ENGINEERING | C40: 008535 | D40: THAILAND | E40: USD | F40: T P | G40: N | H40: Y | J40: CPI | M40: 선불
...

Sheet ICO
A1: Model | B1: Option | C1: Price | D1: Remarks | E1: Key
A2: SA003 | B2: SA003 | C2: 143914.69 | E2: =A2&B2 -> SA003SA003
A3: SA003 | B3: Bush | C3: 0 | D3: FREE | E3: =A3&B3 -> SA003Bush
A4: SA003 | B4: Bush-SQ | C4: 0 | D4: N/A | E4: =A4&B4 -> SA003Bush-SQ
A5: SA003 | B5: Bush-STAR | C5: 0 | D5: N/A | E5: =A5&B5 -> SA003Bush-STAR
A6: SA003 | B6: ALS | C6: 0 | D6: FREE | E6: =A6&B6 -> SA003ALS
A7: SA003 | B7: ATS | C7: 0 | D7: N/A | E7: =A7&B7 -> SA003ATS
A8: SA003 | B8: EXT | C8: 71957.345 | E8: =A8&B8 -> SA003EXT
A9: SA003 | B9: LCU | C9: 0 | D9: N/A | E9: =A9&B9 -> SA003LCU
A10: SA003 | B10: INTEGRAL | C10: 0 | D10: N/A | E10: =A10&B10 -> SA003INTEGRAL
A11: SA003 | B11: PIU | C11: 0 | D11: N/A | E11: =A11&B11 -> SA003PIU
A12: SA003 | B12: CPT+PIU | C12: 0 | D12: N/A | E12: =A12&B12 -> SA003CPT+PIU
A13: SA003 | B13: PCU+PIU | C13: 0 | D13: N/A | E13: =A13&B13 -> SA003PCU+PIU
A14: SA003 | B14: IMS | C14: 0 | D14: N/A | E14: =A14&B14 -> SA003IMS
A15: SA003 | B15: DC24V | C15: 0 | D15: FREE | E15: =A15&B15 -> SA003DC24V
A16: SA003 | B16: BLDC | C16: 0 | D16: N/A | E16: =A16&B16 -> SA003BLDC
A17: SA003 | B17: -40 | C17: 0 | D17: N/A | E17: =A17&B17 -> SA003-40
A18: SA003 | B18: -60 | C18: 0 | D18: N/A | E18: =A18&B18 -> SA003-60
A19: SA003 | B19: EXP | C19: 0 | D19: N/A | E19: =A19&B19 -> SA003EXP
A20: SA003 | B20: SCP | C20: 0 | D20: N/A | E20: =A20&B20 -> SA003SCP
A21: SA003 | B21: Modbus, Profibus | C21: 791530.79 | E21: =A21&B21 -> SA003Modbus, Profibus
A22: SA003 | B22: HART, Foundation Fieldbus | C22: 0 | D22: N/A | E22: =A22&B22 -> SA003HART, Foundation Fieldbus
A23: SA005 | B23: SA005 | C23: 175575.92 | E23: =A23&B23 -> SA005SA005
A24: SA005 | B24: Bush | C24: 0 | D24: FREE | E24: =A24&B24 -> SA005Bush
A25: SA005 | B25: Bush-SQ | C25: 0 | D25: N/A | E25: =A25&B25 -> SA005Bush-SQ
A26: SA005 | B26: Bush-STAR | C26: 0 | D26: N/A | E26: =A26&B26 -> SA005Bush-STAR
A27: SA005 | B27: ALS | C27: 0 | D27: FREE | E27: =A27&B27 -> SA005ALS
A28: SA005 | B28: ATS | C28: 0 | D28: N/A | E28: =A28&B28 -> SA005ATS
A29: SA005 | B29: EXT | C29: 71957.345 | E29: =A29&B29 -> SA005EXT
A30: SA005 | B30: LCU | C30: 0 | D30: N/A | E30: =A30&B30 -> SA005LCU
A31: SA005 | B31: INTEGRAL | C31: 0 | D31: N/A | E31: =A31&B31 -> SA005INTEGRAL
A32: SA005 | B32: PIU | C32: 0 | D32: N/A | E32: =A32&B32 -> SA005PIU
A33: SA005 | B33: CPT+PIU | C33: 0 | D33: N/A | E33: =A33&B33 -> SA005CPT+PIU
A34: SA005 | B34: PCU+PIU | C34: 0 | D34: N/A | E34: =A34&B34 -> SA005PCU+PIU
A35: SA005 | B35: IMS | C35: 0 | D35: N/A | E35: =A35&B35 -> SA005IMS
A36: SA005 | B36: DC24V | C36: 0 | D36: FREE | E36: =A36&B36 -> SA005DC24V
A37: SA005 | B37: BLDC | C37: 0 | D37: N/A | E37: =A37&B37 -> SA005BLDC
A38: SA005 | B38: -40 | C38: 0 | D38: N/A | E38: =A38&B38 -> SA005-40
A39: SA005 | B39: -60 | C39: 0 | D39: N/A | E39: =A39&B39 -> SA005-60
A40: SA005 | B40: EXP | C40: 0 | D40: N/A | E40: =A40&B40 -> SA005EXP
...

Sheet Sheet1
B2: 제이케이콘트롤 | D2: CPI | F2: 1279970 | G2: NA038 | H2: KRW | I2: 1 | J2: 1288000 | K2: =표3[[#This Row],[Item qty]]*표3[[#This Row],[Sales Unit Price]] -> 19250000 | L2: {=_xlfn.XLOOKUP($BB2&$BB2,ICO!$E:$E,ICO!$C:$C,0)+SUMPRODUCT((AW2:BP2="Y")*_xlfn.XLOOKUP($BB2&AW$1:BP$1,ICO!$E:$E,ICO!$C:$C,0))} -> 0 | M2: =표3[[#This Row],[ICO Unit]]*표3[[#This Row],[Item qty]] -> 20294842 | N2: DDP | P2: 이용욱 | R2: 46030 | T2: 46050 | U2: TBD | X2: 220V-1Ph-60Hz | AF2: ◇17 | AG2: Y (BFV200A) 신우밸브 사급 | AL2: 내장 PCU | AN2: IP67 | AO2: PF 3/4" | AP2: M/S | AV2: NA038 | AW2: Y | AX2: Y | BE2: Y | BJ2: Y
B8: 제이케이콘트롤 | D8: CPI | F8: 1279970 | G8: NA038 with BFV | H8: KRW | I8: 22 | J8: 875000 | K8: =표3[[#This Row],[Item qty]]*표3[[#This Row],[Sales Unit Price]] -> 4050000 | L8: {=_xlfn.XLOOKUP($BB8&$BB8,ICO!$E:$E,ICO!$C:$C,0)+SUMPRODUCT((AW8:BP8="Y")*_xlfn.XLOOKUP($BB8&AW$1:BP$1,ICO!$E:$E,ICO!$C:$C,0))} -> 0 | M8: =표3[[#This Row],[ICO Unit]]*표3[[#This Row],[Item qty]] -> 0 | N8: DDP | P8: 이용욱 | T8: 46059
